<?xml version='1.0' encoding='utf-8'?>
<robot name="Arm">
    <link name="Arm_Base_V3_v1">
        <inertial>
            <origin xyz="0.035741081688612224 -0.004573076139556275 -0.024836922956550288" rpy="0.0 0.0 0.0" />
            <mass value="0.2341580521278728" />
            <inertia ixx="6.376703858322182e-05" iyy="0.00010626754288763267" izz="6.937757583855239e-05" ixy="1.2581861591546004e-06" iyz="2.0265805369798924e-07" ixz="-2.1274268053163896e-08" />
        </inertial>
        <visual name="Arm-Base-V3-v1_visual">
            <origin xyz="0.0 0.0 0.0" rpy="0.0 0.0 0.0" />
            <geometry>
                <mesh filename="meshes/Arm-Base-V3-v1.stl" scale="0.001 0.001 0.001" />
            </geometry>
        </visual>
        <collision name="Arm-Base-V3-v1_collision">
            <origin xyz="0.0 0.0 0.0" rpy="0.0 0.0 0.0" />
            <geometry>
                <mesh filename="meshes/Arm-Base-V3-v1.stl" scale="0.001 0.001 0.001" />
            </geometry>
        </collision>
    </link>
    <link name="Feetech_Servo_Motor_v1">
        <inertial>
            <origin xyz="-2.019100824313114e-09 -0.02170090897026995 0.01661164263349681" rpy="0.0 -0.0 4.861730685829017e-63" />
            <mass value="0.2646673118671472" />
            <inertia ixx="6.542852314588894e-05" iyy="3.4338660748983775e-05" izz="5.709510021731243e-05" ixy="-2.753948230582109e-20" iyz="-1.394302603508647e-07" ixz="6.98238585306517e-18" />
        </inertial>
        <visual name="Feetech-Servo-Motor-v1_visual">
            <origin xyz="-2.019100819872222e-09 -0.02249999999999999 0.01674999837598785" rpy="1.5707963267948968 1.081079670228745e-14 2.3673873319212803e-16" />
            <geometry>
                <mesh filename="meshes/Feetech-Servo-Motor-v1.stl" scale="0.001 0.001 0.001" />
            </geometry>
        </visual>
        <collision name="Feetech-Servo-Motor-v1_collision">
            <origin xyz="-2.019100819872222e-09 -0.02249999999999999 0.01674999837598785" rpy="1.5707963267948968 1.081079670228745e-14 2.3673873319212803e-16" />
            <geometry>
                <mesh filename="meshes/Feetech-Servo-Motor-v1.stl" scale="0.001 0.001 0.001" />
            </geometry>
        </collision>
    </link>
    <link name="Shoulder_With_Gearbox_V3_v1">
        <inertial>
            <origin xyz="0.0020342162144027266 3.592756842557554e-08 0.03581790974840599" rpy="0.0 -0.0 0.0" />
            <mass value="0.8441393911108179" />
            <inertia ixx="0.0007514593284477789" iyy="0.00045972127080808403" izz="0.0006762215851131785" ixy="1.6959038445346067e-10" iyz="2.1809406593919145e-10" ixz="-6.433524319731602e-05" />
        </inertial>
        <visual name="Shoulder-With-Gearbox-V3-v1_visual">
            <origin xyz="-2.019100882044711e-09 -1.6240121805677355e-09 -0.0027500000000000124" rpy="-1.5707963267949046 -1.5707963267948963 0" />
            <geometry>
                <mesh filename="meshes/Shoulder-With-Gearbox-V3-v1.stl" scale="0.001 0.001 0.001" />
            </geometry>
        </visual>
        <collision name="Shoulder-With-Gearbox-V3-v1_collision">
            <origin xyz="-2.019100882044711e-09 -1.6240121805677355e-09 -0.0027500000000000124" rpy="-1.5707963267949046 -1.5707963267948963 0" />
            <geometry>
                <mesh filename="meshes/Shoulder-With-Gearbox-V3-v1.stl" scale="0.001 0.001 0.001" />
            </geometry>
        </collision>
    </link>
    <link name="Feetech_Servo_Motor_v1_1">
        <inertial>
            <origin xyz="-0.01661164627660981 0.021700908970269977 1.6240121900740201e-09" rpy="0.0 -0.0 0.0" />
            <mass value="0.2646673118671472" />
            <inertia ixx="5.709510021731324e-05" iyy="3.433866074898403e-05" izz="6.542852314588964e-05" ixy="-1.3943026035080543e-07" iyz="-3.218725199566341e-20" ixz="7.015126869160115e-18" />
        </inertial>
        <visual name="Feetech-Servo-Motor-v1-1_visual">
            <origin xyz="-0.01675000201910085 0.02250000000000001 1.6240121886168524e-09" rpy="-1.570796326794897 1.570796326794889 0" />
            <geometry>
                <mesh filename="meshes/Feetech-Servo-Motor-v1-1.stl" scale="0.001 0.001 0.001" />
            </geometry>
        </visual>
        <collision name="Feetech-Servo-Motor-v1-1_collision">
            <origin xyz="-0.01675000201910085 0.02250000000000001 1.6240121886168524e-09" rpy="-1.570796326794897 1.570796326794889 0" />
            <geometry>
                <mesh filename="meshes/Feetech-Servo-Motor-v1-1.stl" scale="0.001 0.001 0.001" />
            </geometry>
        </collision>
    </link>
    <link name="Arm_Bicep_v1">
        <inertial>
            <origin xyz="0.027137344568476402 -0.0028434882503882196 -0.06866704528993729" rpy="0.0 -0.0 0.0" />
            <mass value="1.2428968473066873" />
            <inertia ixx="0.0022030845028904594" iyy="0.0035105848595467226" izz="0.0014550434330134815" ixy="-2.8160951144133833e-06" iyz="1.8485970020174153e-06" ixz="-0.00040028422176472886" />
        </inertial>
        <visual name="Arm-Bicep-v1_visual">
            <origin xyz="0.053649997980899214 -0.002749998375987544 4.197531211502792e-13" rpy="-1.5707963267949043 1.5707963267948963 0" />
            <geometry>
                <mesh filename="meshes/Arm-Bicep-v1.stl" scale="0.001 0.001 0.001" />
            </geometry>
        </visual>
        <collision name="Arm-Bicep-v1_collision">
            <origin xyz="0.053649997980899214 -0.002749998375987544 4.197531211502792e-13" rpy="-1.5707963267949043 1.5707963267948963 0" />
            <geometry>
                <mesh filename="meshes/Arm-Bicep-v1.stl" scale="0.001 0.001 0.001" />
            </geometry>
        </collision>
    </link>
    <link name="Feetech_Servo_Motor_v1_2">
        <inertial>
            <origin xyz="-0.016611646276609854 0.021700908969850267 1.6240121517019369e-09" rpy="0.0 -0.0 2.1895288505075267e-47" />
            <mass value="0.2646673118671472" />
            <inertia ixx="5.709510021731353e-05" iyy="3.43386607489838e-05" izz="6.542852314588693e-05" ixy="-1.394302603509129e-07" iyz="-3.852782015877678e-20" ixz="6.939436772730584e-18" />
        </inertial>
        <visual name="Feetech-Servo-Motor-v1-2_visual">
            <origin xyz="-0.016750002019100894 0.022499999999580318 1.6240121497590465e-09" rpy="-1.570796326794897 1.5707963267948852 0" />
            <geometry>
                <mesh filename="meshes/Feetech-Servo-Motor-v1-2.stl" scale="0.001 0.001 0.001" />
            </geometry>
        </visual>
        <collision name="Feetech-Servo-Motor-v1-2_collision">
            <origin xyz="-0.016750002019100894 0.022499999999580318 1.6240121497590465e-09" rpy="-1.570796326794897 1.5707963267948852 0" />
            <geometry>
                <mesh filename="meshes/Feetech-Servo-Motor-v1-2.stl" scale="0.001 0.001 0.001" />
            </geometry>
        </collision>
    </link>
    <link name="Arm_Forearm_v1">
        <inertial>
            <origin xyz="2.3642309062195112e-05 -0.0027410450478023104 -0.07049677204078193" rpy="0.0 -1.349401336733507e-79 0.0" />
            <mass value="1.1540811630894723" />
            <inertia ixx="0.0019372258470567129" iyy="0.002617941632487954" izz="0.0008128358612115604" ixy="-4.160939794933725e-11" iyz="4.439918589332589e-07" ixz="1.2980200860105463e-06" />
        </inertial>
        <visual name="Arm-Forearm-v1_visual">
            <origin xyz="0.034824997980899206 -0.0027499983759876746 8.399325679420145e-13" rpy="-1.5707963267949077 1.5707963267948963 0" />
            <geometry>
                <mesh filename="meshes/Arm-Forearm-v1.stl" scale="0.001 0.001 0.001" />
            </geometry>
        </visual>
        <collision name="Arm-Forearm-v1_collision">
            <origin xyz="0.034824997980899206 -0.0027499983759876746 8.399325679420145e-13" rpy="-1.5707963267949077 1.5707963267948963 0" />
            <geometry>
                <mesh filename="meshes/Arm-Forearm-v1.stl" scale="0.001 0.001 0.001" />
            </geometry>
        </collision>
    </link>
    <link name="Feetech_Servo_Motor_v1_3">
        <inertial>
            <origin xyz="0.038523313723390074 -0.40995090896943004 0.004913778375987986" rpy="0.0 -0.0 0.0" />
            <mass value="0.2646673118671472" />
            <inertia ixx="5.7095100217320616e-05" iyy="3.433866074898365e-05" izz="6.542852314588704e-05" ixy="1.3943026035048017e-07" iyz="0.0" ixz="-6.959222694641332e-18" />
        </inertial>
        <visual name="Feetech-Servo-Motor-v1-3_visual">
            <origin xyz="0.03838495798089903 -0.4107499999991601 0.004913778375987988" rpy="1.5707963267948961 -1.5707963267948863 0" />
            <geometry>
                <mesh filename="meshes/Feetech-Servo-Motor-v1-3.stl" scale="0.001 0.001 0.001" />
            </geometry>
        </visual>
        <collision name="Feetech-Servo-Motor-v1-3_collision">
            <origin xyz="0.03838495798089903 -0.4107499999991601 0.004913778375987988" rpy="1.5707963267948961 -1.5707963267948863 0" />
            <geometry>
                <mesh filename="meshes/Feetech-Servo-Motor-v1-3.stl" scale="0.001 0.001 0.001" />
            </geometry>
        </collision>
    </link>
    <link name="Arm_Wrist_v1">
        <inertial>
            <origin xyz="-0.0015547232516760889 0.0027500039444255 -0.03382813962605368" rpy="0.0 -0.0 0.0" />
            <mass value="0.49175094039824324" />
            <inertia ixx="0.0001939318174210153" iyy="0.00046306236904437956" izz="0.00038490076882158233" ixy="-1.8722882647536788e-11" iyz="8.860218432212249e-11" ixz="-3.439221666665795e-05" />
        </inertial>
        <visual name="Arm-Wrist-v1_visual">
            <origin xyz="-2.0191010374759343e-09 0.00275000162401189 8.36593017083942e-13" rpy="1.5707963267948866 1.5707963267948064 0" />
            <geometry>
                <mesh filename="meshes/Arm-Wrist-v1.stl" scale="0.001 0.001 0.001" />
            </geometry>
        </visual>
        <collision name="Arm-Wrist-v1_collision">
            <origin xyz="-2.0191010374759343e-09 0.00275000162401189 8.36593017083942e-13" rpy="1.5707963267948866 1.5707963267948064 0" />
            <geometry>
                <mesh filename="meshes/Arm-Wrist-v1.stl" scale="0.001 0.001 0.001" />
            </geometry>
        </collision>
    </link>
    <link name="Feetech_Servo_Motor_v1_4">
        <inertial>
            <origin xyz="0.02608586695117341 -0.4741383557416561 0.0021637783759882213" rpy="0.0 -0.0 0.0" />
            <mass value="0.2646673118671472" />
            <inertia ixx="3.433866074898512e-05" iyy="5.7095100217311535e-05" izz="6.542852314590092e-05" ixy="1.3943026034874545e-07" iyz="-7.101524229780054e-18" ixz="2.998496633280223e-19" />
        </inertial>
        <visual name="Feetech-Servo-Motor-v1-4_visual">
            <origin xyz="0.02688495798090343 -0.473999999999165 0.002163778375988214" rpy="-8.906029716668403e-14 1.5707963267948872 0" />
            <geometry>
                <mesh filename="meshes/Feetech-Servo-Motor-v1-4.stl" scale="0.001 0.001 0.001" />
            </geometry>
        </visual>
        <collision name="Feetech-Servo-Motor-v1-4_collision">
            <origin xyz="0.02688495798090343 -0.473999999999165 0.002163778375988214" rpy="-8.906029716668403e-14 1.5707963267948872 0" />
            <geometry>
                <mesh filename="meshes/Feetech-Servo-Motor-v1-4.stl" scale="0.001 0.001 0.001" />
            </geometry>
        </collision>
    </link>
    <link name="Gripper_Base_Back_v1">
        <inertial>
            <origin xyz="0.004232817461800136 -1.7621744387547045e-07 0.023047641156723843" rpy="0.0 -0.0 0.0" />
            <mass value="0.4863478754766551" />
            <inertia ixx="0.00020378471536269815" iyy="0.0002577552333986599" izz="0.0003815579271776781" ixy="2.6050383458448706e-09" iyz="-1.6939541811356734e-09" ixz="1.690862097191749e-05" />
        </inertial>
        <visual name="Gripper-Base-Back-v1_visual">
            <origin xyz="0.03999999798090958 -1.6240120881416687e-09 0.050999999999159655" rpy="-3.141592653589784 1.5707963267948069 0" />
            <geometry>
                <mesh filename="meshes/Gripper-Base-Back-v1.stl" scale="0.001 0.001 0.001" />
            </geometry>
        </visual>
        <collision name="Gripper-Base-Back-v1_collision">
            <origin xyz="0.03999999798090958 -1.6240120881416687e-09 0.050999999999159655" rpy="-3.141592653589784 1.5707963267948069 0" />
            <geometry>
                <mesh filename="meshes/Gripper-Base-Back-v1.stl" scale="0.001 0.001 0.001" />
            </geometry>
        </collision>
    </link>
    <link name="Feetech_Servo_Motor_v1_5">
        <inertial>
            <origin xyz="-1.6240117750587757e-09 -0.01788835574165347 -0.013299089010636816" rpy="0.0 -0.0 0.0" />
            <mass value="0.2646673118671472" />
            <inertia ixx="6.542852314589398e-05" iyy="5.70951002173127e-05" izz="3.4338660748992056e-05" ixy="7.047314121155779e-18" iyz="1.394302603522149e-07" ixz="-2.8460307027744443e-19" />
        </inertial>
        <visual name="Feetech-Servo-Motor-v1-5_visual">
            <origin xyz="-1.6240117675647702e-09 -0.01774999999916247 -0.012499997980906766" rpy="8.98288916178554e-14 9.606648933717141e-15 1.998401444325277e-15" />
            <geometry>
                <mesh filename="meshes/Feetech-Servo-Motor-v1-5.stl" scale="0.001 0.001 0.001" />
            </geometry>
        </visual>
        <collision name="Feetech-Servo-Motor-v1-5_collision">
            <origin xyz="-1.6240117675647702e-09 -0.01774999999916247 -0.012499997980906766" rpy="8.98288916178554e-14 9.606648933717141e-15 1.998401444325277e-15" />
            <geometry>
                <mesh filename="meshes/Feetech-Servo-Motor-v1-5.stl" scale="0.001 0.001 0.001" />
            </geometry>
        </collision>
    </link>
    <link name="Gripper_Base_Front_Angled_Camera_v1">
        <inertial>
            <origin xyz="-0.022724959635186594 0.006788434122913642 0.028566226124116714" rpy="0.0 -0.0 0.0" />
            <mass value="0.4069950577507868" />
            <inertia ixx="0.00023363907866320865" iyy="0.0006068219550467736" izz="0.0003985555599830687" ixy="-2.1186888056042193e-05" iyz="-2.272493928862432e-06" ixz="-3.807697974938872e-06" />
        </inertial>
        <visual name="Gripper-Base-Front-Angled-Camera-v1_visual">
            <origin xyz="-0.029250001624033406 0.016499999999159628 0.06999999798089084" rpy="-3.1415926535897833 8.980199662771414e-14 -1.5707963267948983" />
            <geometry>
                <mesh filename="meshes/Gripper-Base-Front-Angled-Camera-v1.stl" scale="0.001 0.001 0.001" />
            </geometry>
        </visual>
        <collision name="Gripper-Base-Front-Angled-Camera-v1_collision">
            <origin xyz="-0.029250001624033406 0.016499999999159628 0.06999999798089084" rpy="-3.1415926535897833 8.980199662771414e-14 -1.5707963267948983" />
            <geometry>
                <mesh filename="meshes/Gripper-Base-Front-Angled-Camera-v1.stl" scale="0.001 0.001 0.001" />
            </geometry>
        </collision>
    </link>
    <link name="Gripper_Finger_v1">
        <inertial>
            <origin xyz="0.023124627948339263 0.005200395937106546 -0.01176945456522276" rpy="4.1353190920861306e-48 -0.0 0.0" />
            <mass value="0.2580797904913778" />
            <inertia ixx="0.00015785315323396665" iyy="0.00015506346315172226" izz="0.0001967272170521559" ixy="1.5464066944840963e-05" iyz="-3.4886870027287117e-05" ixz="1.1992083172602303e-05" />
        </inertial>
        <visual name="Gripper-Finger-v1_visual">
            <origin xyz="0.04899999837596804 -0.01598436523089288 -0.0024999999991682387" rpy="3.1415926535897913 -8.990917326691274e-14 1.5707963267949072" />
            <geometry>
                <mesh filename="meshes/Gripper-Finger-v1.stl" scale="0.001 0.001 0.001" />
            </geometry>
        </visual>
        <collision name="Gripper-Finger-v1_collision">
            <origin xyz="0.04899999837596804 -0.01598436523089288 -0.0024999999991682387" rpy="3.1415926535897913 -8.990917326691274e-14 1.5707963267949072" />
            <geometry>
                <mesh filename="meshes/Gripper-Finger-v1.stl" scale="0.001 0.001 0.001" />
            </geometry>
        </collision>
    </link>
    <link name="Gripper_Finger_v1_1">
        <inertial>
            <origin xyz="-0.0021030001938665156 0.032624631196405185 -0.01676945456521679" rpy="0.0 -4.183014959432442e-90 0.0" />
            <mass value="0.2580797904913778" />
            <inertia ixx="0.00015506346315172226" iyy="0.0001578531532339944" izz="0.0001967272170521569" ixy="-1.5464066944842247e-05" iyz="1.19920831726007e-05" ixz="3.488687002727725e-05" />
        </inertial>
        <visual name="Gripper-Finger-v1-1_visual">
            <origin xyz="0.01908176097413098 0.05850000162403405 -0.007499999999158576" rpy="-3.1415926535897913 9.041287327296821e-14 -3.141592653589782" />
            <geometry>
                <mesh filename="meshes/Gripper-Finger-v1-1.stl" scale="0.001 0.001 0.001" />
            </geometry>
        </visual>
        <collision name="Gripper-Finger-v1-1_collision">
            <origin xyz="0.01908176097413098 0.05850000162403405 -0.007499999999158576" rpy="-3.1415926535897913 9.041287327296821e-14 -3.141592653589782" />
            <geometry>
                <mesh filename="meshes/Gripper-Finger-v1-1.stl" scale="0.001 0.001 0.001" />
            </geometry>
        </collision>
    </link>
    <joint name="Arm_Base_V3_v1_Rigid_1" type="fixed">
        <origin xyz="0.05233622014901163 6.859801863787153e-19 -0.024715040894069628" rpy="-8.031609262326351e-32 -1.5707963267948828 0" />
        <parent link="Arm_Base_V3_v1" />
        <child link="Feetech_Servo_Motor_v1" />
    </joint>
    <joint name="Feetech_Servo_Motor_v1_Revolute_2" type="revolute">
        <origin xyz="5.329070518200751e-17 -0.03499999999999999 0.01675000000000001" rpy="1.5707963267948966 3.1157368034048998e-15 1.559600974533801e-46" />
        <parent link="Feetech_Servo_Motor_v1" />
        <child link="Shoulder_With_Gearbox_V3_v1" />
        <axis xyz="4.370308408487244e-32 -1.0 -0.0" />
        <limit lower="0.0" upper="3.141593" effort="1000000" velocity="1000000" />
    </joint>
    <joint name="Shoulder_With_Gearbox_V3_v1_Rigid_4" type="fixed">
        <origin xyz="0.017425000000000003 0.0 0.03825" rpy="1.5707963267948966 -2.21816814771825e-32 4.370308408487244e-32" />
        <parent link="Shoulder_With_Gearbox_V3_v1" />
        <child link="Feetech_Servo_Motor_v1_1" />
    </joint>
    <joint name="Feetech_Servo_Motor_v1_1_Revolute_5" type="revolute">
        <origin xyz="-0.0345 0.03499999999999999 0.0" rpy="1.5707963267948966 -0.0 -2.21816814771825e-32" />
        <parent link="Feetech_Servo_Motor_v1_1" />
        <child link="Arm_Bicep_v1" />
        <axis xyz="-1.0 -0.0 0.0" />
        <limit lower="1.570796" upper="4.712389" effort="1000000" velocity="1000000" />
    </joint>
    <joint name="Arm_Bicep_v1_Rigid_6" type="fixed">
        <origin xyz="0.03625 -0.00275 -0.1225" rpy="-1.570796326794896 1.6140921240872863e-31 5.290890058994736e-63" />
        <parent link="Arm_Bicep_v1" />
        <child link="Feetech_Servo_Motor_v1_2" />
    </joint>
    <joint name="Feetech_Servo_Motor_v1_2_Revolute_7" type="revolute">
        <origin xyz="-0.01675000000000003 0.03500000000000004 -7.771561172376097e-18" rpy="1.5707963267948963 -2.4651903288156674e-32 -1.6140921240872852e-31" />
        <parent link="Feetech_Servo_Motor_v1_2" />
        <child link="Arm_Forearm_v1" />
        <axis xyz="-0.9999999999999989 -1.1102230246251205e-16 -5.338809236774413e-16" />
        <limit lower="1.570796" upper="4.712389" effort="1000000" velocity="1000000" />
    </joint>
    <joint name="Arm_Forearm_v1_Rigid_8" type="fixed">
        <origin xyz="-0.03770996000000019 0.0021637800000000014 0.2657500000000005" rpy="1.5707963267948966 -2.0905669563572298e-64 -2.465190328815666e-32" />
        <parent link="Arm_Forearm_v1" />
        <child link="Feetech_Servo_Motor_v1_3" />
    </joint>
    <joint name="Feetech_Servo_Motor_v1_3_Revolute_9" type="revolute">
        <origin xyz="0.03838496 -0.42325 0.0049137799999999995" rpy="-1.5707963267948966 -2.1019476964872216e-45 2.165785361126662e-77" />
        <parent link="Feetech_Servo_Motor_v1_3" />
        <child link="Arm_Wrist_v1" />
        <axis xyz="-1.0000000000000029 -8.326672684688682e-16 -1.9075514175142588e-16" />
        <limit lower="-1.570796" upper="1.570796" effort="1000000" velocity="1000000" />
    </joint>
    <joint name="Arm_Wrist_v1_Rigid_10" type="fixed">
        <origin xyz="-0.038384959999999975 0.0049137800000000394 0.42325000000000124" rpy="1.5707963267948966 -1.0828926805690129e-77 2.101947696487225e-45" />
        <parent link="Arm_Wrist_v1" />
        <child link="Feetech_Servo_Motor_v1_4" />
    </joint>
    <joint name="Feetech_Servo_Motor_v1_4_Revolute_11" type="revolute">
        <origin xyz="0.039384960000000004 -0.49174999999999996 0.00216378" rpy="1.5707963267948966 -0.0 2.465190328815662e-32" />
        <parent link="Feetech_Servo_Motor_v1_4" />
        <child link="Gripper_Base_Back_v1" />
        <axis xyz="-2.465190328815662e-32 1.162272669189553e-29 1.0" />
        <limit lower="0.0" upper="6.283185" effort="1000000" velocity="1000000" />
    </joint>
    <joint name="Gripper_Base_Back_v1_Rigid_12" type="fixed">
        <origin xyz="0.0 0.0 0.0020000000000000287" rpy="-1.5707963267948966 1.162272669189553e-29 1.5707963267948966" />
        <parent link="Gripper_Base_Back_v1" />
        <child link="Feetech_Servo_Motor_v1_5" />
    </joint>
    <joint name="Gripper_Base_Back_v1_Rigid_13" type="fixed">
        <origin xyz="-0.03 0.029249999999999998 0.03450000000000003" rpy="1.5707963267948966 1.162272669189553e-29 1.5707963267948966" />
        <parent link="Gripper_Base_Back_v1" />
        <child link="Gripper_Base_Front_Angled_Camera_v1" />
    </joint>
    <joint name="Gripper_Base_Front_Angled_Camera_v1_Slider_14" type="prismatic">
        <origin xyz="-0.055 0.012000000000000028 -0.01" rpy="1.5707963267948966 -5.36708215504344e-31 5.551115123125783e-17" />
        <parent link="Gripper_Base_Front_Angled_Camera_v1" />
        <child link="Gripper_Finger_v1" />
        <axis xyz="4.552888492875278e-30 -1.0 -0.0" />
        <limit lower="-0.1075" upper="-0.03" effort="1000000" velocity="1000000" />
    </joint>
    <joint name="Gripper_Base_Front_Angled_Camera_v1_Slider_15" type="prismatic">
        <origin xyz="0.007000000000000002 0.012000000000000028 0.07" rpy="1.5707963267948966 -1.5707963267948966 0" />
        <parent link="Gripper_Base_Front_Angled_Camera_v1" />
        <child link="Gripper_Finger_v1_1" />
        <axis xyz="1.0 4.552888492875278e-30 0.0" />
        <limit lower="-0.065" upper="0.0" effort="1000000" velocity="1000000" />
    </joint>
</robot>